<sdf version='1.7'>
  <model name='ranger_mini_v2'>
    <link name='base_footprint'>
      <inertial>
        <pose>0 0 0 0 -0 0</pose>
        <mass>10</mass>
        <inertia>
          <ixx>1</ixx>
          <ixy>0</ixy>
          <ixz>0</ixz>
          <iyy>1</iyy>
          <iyz>0</iyz>
          <izz>1</izz>
        </inertia>
      </inertial>
      <collision name='base_footprint_fixed_joint_lump__base_link_collision'>
        <pose>0 0 -0.1 0 -0 0</pose>
        <geometry>
          <box>
            <size>0.5 0.35 0.2</size>
          </box>
        </geometry>
      </collision>
      <visual name='base_footprint_fixed_joint_lump__base_link_visual'>
        <pose>0 0 0 1.57 0 3.14</pose>
        <geometry>
          <mesh>
            <scale>1 1 1</scale>
            <uri>model://ranger_mini_v2/meshes/ranger_base.dae</uri>
          </mesh>
        </geometry>
      </visual>
    </link>
    <joint name='fl_steering_wheel' type='revolute'>
      <pose relative_to='base_footprint'>0.23 0.206 -0.1 0 -0 0</pose>
      <parent>base_footprint</parent>
      <child>fl_steering_wheel_link</child>
      <axis>
        <xyz>0 0 1</xyz>
        <limit>
          <lower>-2.1</lower>
          <upper>2.1</upper>
          <effort>5</effort>
          <velocity>6.28</velocity>
        </limit>
        <dynamics>
          <spring_reference>0</spring_reference>
          <spring_stiffness>0</spring_stiffness>
        </dynamics>
      </axis>
    </joint>
    <link name='fl_steering_wheel_link'>
      <pose relative_to='fl_steering_wheel'>0 0 0 0 -0 0</pose>
      <inertial>
        <pose>0 0 0 0 -0 0</pose>
        <mass>1</mass>
        <inertia>
          <ixx>0.01</ixx>
          <ixy>0</ixy>
          <ixz>0</ixz>
          <iyy>0.01</iyy>
          <iyz>0</iyz>
          <izz>0.01</izz>
        </inertia>
      </inertial>
      <collision name='fl_steering_wheel_link_collision'>
        <pose>0 0 0.008 0 -0 0</pose>
        <geometry>
          <cylinder>
            <length>0.001</length>
            <radius>0.001</radius>
          </cylinder>
        </geometry>
      </collision>
      <collision name='fl_steering_wheel_link_collision_1'>
        <pose>0 0 0 0 -0 0</pose>
        <geometry>
          <cylinder>
            <length>0.001</length>
            <radius>0.001</radius>
          </cylinder>
        </geometry>
      </collision>
      <visual name='fl_steering_wheel_link_visual'>
        <pose>-0.23 -0.194 0.1 1.57 0 3.14</pose>
        <geometry>
          <mesh>
            <scale>1 1 1</scale>
            <uri>model://ranger_mini_v2/meshes/fl.dae</uri>
          </mesh>
        </geometry>
      </visual>
    </link>
    <joint name='fl_wheel' type='revolute'>
      <pose relative_to='fl_steering_wheel_link'>0.03 0.01 -0.12 0 -0 0</pose>
      <parent>fl_steering_wheel_link</parent>
      <child>fl_wheel_link</child>
      <axis>
        <xyz>0 1 0</xyz>
        <limit>
          <lower>-1e+16</lower>
          <upper>1e+16</upper>
        </limit>
        <dynamics>
          <spring_reference>0</spring_reference>
          <spring_stiffness>0</spring_stiffness>
        </dynamics>
      </axis>
    </joint>
    <link name='fl_wheel_link'>
      <pose relative_to='fl_wheel'>0 0 0 0 -0 0</pose>
      <inertial>
        <pose>0 0 0 0 -0 0</pose>
        <mass>8</mass>
        <inertia>
          <ixx>0.1171</ixx>
          <ixy>0</ixy>
          <ixz>0</ixz>
          <iyy>0.1361</iyy>
          <iyz>0</iyz>
          <izz>0.1171</izz>
        </inertia>
      </inertial>
      <collision name='fl_wheel_link_collision'>
        <pose>0 0 0 1.57 -0 0</pose>
        <geometry>
          <cylinder>
            <length>0.08</length>
            <radius>0.08</radius>
          </cylinder>
        </geometry>
      </collision>
      <visual name='fl_wheel_link_visual'>
        <pose>0 0 0 1.57 -0 0</pose>
        <geometry>
          <cylinder>
            <length>0.01</length>
            <radius>0.01</radius>
          </cylinder>
        </geometry>
      </visual>
    </link>
    <joint name='fr_steering_wheel' type='revolute'>
      <pose relative_to='base_footprint'>0.23 -0.206 -0.1 0 -0 0</pose>
      <parent>base_footprint</parent>
      <child>fr_steering_wheel_link</child>
      <axis>
        <xyz>0 0 1</xyz>
        <limit>
          <lower>-2.1</lower>
          <upper>2.1</upper>
          <effort>5</effort>
          <velocity>6.28</velocity>
        </limit>
        <dynamics>
          <spring_reference>0</spring_reference>
          <spring_stiffness>0</spring_stiffness>
        </dynamics>
      </axis>
    </joint>
    <link name='fr_steering_wheel_link'>
      <pose relative_to='fr_steering_wheel'>0 0 0 0 -0 0</pose>
      <inertial>
        <pose>0 0 0 0 -0 0</pose>
        <mass>1</mass>
        <inertia>
          <ixx>0.01</ixx>
          <ixy>0</ixy>
          <ixz>0</ixz>
          <iyy>0.01</iyy>
          <iyz>0</iyz>
          <izz>0.01</izz>
        </inertia>
      </inertial>
      <collision name='fr_steering_wheel_link_collision'>
        <pose>0 0 0.008 0 -0 0</pose>
        <geometry>
          <cylinder>
            <length>0.001</length>
            <radius>0.001</radius>
          </cylinder>
        </geometry>
      </collision>
      <visual name='fr_steering_wheel_link_visual'>
        <pose>-0.23 0.194 0.1 1.57 0 3.14</pose>
        <geometry>
          <mesh>
            <scale>1 1 1</scale>
            <uri>model://ranger_mini_v2/meshes/fr.dae</uri>
          </mesh>
        </geometry>
      </visual>
    </link>
    <joint name='fr_wheel' type='revolute'>
      <pose relative_to='fr_steering_wheel_link'>0 0 -0.12 0 -0 0</pose>
      <parent>fr_steering_wheel_link</parent>
      <child>fr_wheel_link</child>
      <axis>
        <xyz>0 1 0</xyz>
        <limit>
          <lower>-1e+16</lower>
          <upper>1e+16</upper>
        </limit>
        <dynamics>
          <spring_reference>0</spring_reference>
          <spring_stiffness>0</spring_stiffness>
        </dynamics>
      </axis>
    </joint>
    <link name='fr_wheel_link'>
      <pose relative_to='fr_wheel'>0 0 0 0 -0 0</pose>
      <inertial>
        <pose>0 0 0 0 -0 0</pose>
        <mass>8</mass>
        <inertia>
          <ixx>0.1171</ixx>
          <ixy>0</ixy>
          <ixz>0</ixz>
          <iyy>0.1361</iyy>
          <iyz>0</iyz>
          <izz>0.1171</izz>
        </inertia>
      </inertial>
      <collision name='fr_wheel_link_collision'>
        <pose>0 0 0 1.57 -0 0</pose>
        <geometry>
          <cylinder>
            <length>0.08</length>
            <radius>0.085</radius>
          </cylinder>
        </geometry>
      </collision>
      <visual name='fr_wheel_link_visual'>
        <pose>0 0 0 1.57 -0 0</pose>
        <geometry>
          <cylinder>
            <length>0.01</length>
            <radius>0.01</radius>
          </cylinder>
        </geometry>
      </visual>
    </link>
    <joint name='rl_steering_wheel' type='revolute'>
      <pose relative_to='base_footprint'>-0.23 0.206 -0.1 0 -0 0</pose>
      <parent>base_footprint</parent>
      <child>rl_steering_wheel_link</child>
      <axis>
        <xyz>0 0 1</xyz>
        <limit>
          <lower>-2.1</lower>
          <upper>2.1</upper>
          <effort>5</effort>
          <velocity>6.28</velocity>
        </limit>
        <dynamics>
          <spring_reference>0</spring_reference>
          <spring_stiffness>0</spring_stiffness>
        </dynamics>
      </axis>
    </joint>
    <link name='rl_steering_wheel_link'>
      <pose relative_to='rl_steering_wheel'>0 0 0 0 -0 0</pose>
      <inertial>
        <pose>0 0 0 0 -0 0</pose>
        <mass>1</mass>
        <inertia>
          <ixx>0.01</ixx>
          <ixy>0</ixy>
          <ixz>0</ixz>
          <iyy>0.01</iyy>
          <iyz>0</iyz>
          <izz>0.01</izz>
        </inertia>
      </inertial>
      <collision name='rl_steering_wheel_link_collision'>
        <pose>0 0 0.008 0 -0 0</pose>
        <geometry>
          <cylinder>
            <length>0.001</length>
            <radius>0.001</radius>
          </cylinder>
        </geometry>
      </collision>
      <visual name='rl_steering_wheel_link_visual'>
        <pose>-0.23 -0.194 0.1 1.57 0 3.14</pose>
        <geometry>
          <mesh>
            <scale>1 1 1</scale>
            <uri>model://ranger_mini_v2/meshes/fl.dae</uri>
          </mesh>
        </geometry>
      </visual>
    </link>
    <joint name='rl_wheel' type='revolute'>
      <pose relative_to='rl_steering_wheel_link'>0 0 -0.12 0 -0 0</pose>
      <parent>rl_steering_wheel_link</parent>
      <child>rl_wheel_link</child>
      <axis>
        <xyz>0 1 0</xyz>
        <limit>
          <lower>-1e+16</lower>
          <upper>1e+16</upper>
        </limit>
        <dynamics>
          <spring_reference>0</spring_reference>
          <spring_stiffness>0</spring_stiffness>
        </dynamics>
      </axis>
    </joint>
    <link name='rl_wheel_link'>
      <pose relative_to='rl_wheel'>0 0 0 0 -0 0</pose>
      <inertial>
        <pose>0 0 0 0 -0 0</pose>
        <mass>8</mass>
        <inertia>
          <ixx>0.1171</ixx>
          <ixy>0</ixy>
          <ixz>0</ixz>
          <iyy>0.1361</iyy>
          <iyz>0</iyz>
          <izz>0.1171</izz>
        </inertia>
      </inertial>
      <collision name='rl_wheel_link_collision'>
        <pose>0 0 0 1.57 -0 0</pose>
        <geometry>
          <cylinder>
            <length>0.08</length>
            <radius>0.08</radius>
          </cylinder>
        </geometry>
      </collision>
      <visual name='rl_wheel_link_visual'>
        <pose>0 0 0 1.57 -0 0</pose>
        <geometry>
          <cylinder>
            <length>0.01</length>
            <radius>0.01</radius>
          </cylinder>
        </geometry>
      </visual>
    </link>
    <joint name='rr_steering_wheel' type='revolute'>
      <pose relative_to='base_footprint'>-0.23 -0.206 -0.1 0 -0 0</pose>
      <parent>base_footprint</parent>
      <child>rr_steering_wheel_link</child>
      <axis>
        <xyz>0 0 1</xyz>
        <limit>
          <lower>-2.1</lower>
          <upper>2.1</upper>
          <effort>5</effort>
          <velocity>6.28</velocity>
        </limit>
        <dynamics>
          <spring_reference>0</spring_reference>
          <spring_stiffness>0</spring_stiffness>
        </dynamics>
      </axis>
    </joint>
    <link name='rr_steering_wheel_link'>
      <pose relative_to='rr_steering_wheel'>0 0 0 0 -0 0</pose>
      <inertial>
        <pose>0 0 0 0 -0 0</pose>
        <mass>1</mass>
        <inertia>
          <ixx>0.01</ixx>
          <ixy>0</ixy>
          <ixz>0</ixz>
          <iyy>0.01</iyy>
          <iyz>0</iyz>
          <izz>0.01</izz>
        </inertia>
      </inertial>
      <collision name='rr_steering_wheel_link_collision'>
        <pose>0 0 0 0 -0 0</pose>
        <geometry>
          <cylinder>
            <length>0.001</length>
            <radius>0.001</radius>
          </cylinder>
        </geometry>
      </collision>
      <visual name='rr_steering_wheel_link_visual'>
        <pose>-0.23 0.194 0.1 1.57 0 3.14</pose>
        <geometry>
          <mesh>
            <scale>1 1 1</scale>
            <uri>model://ranger_mini_v2/meshes/fr.dae</uri>
          </mesh>
        </geometry>
      </visual>
    </link>
    <joint name='rr_wheel' type='revolute'>
      <pose relative_to='rr_steering_wheel_link'>0 0 -0.12 0 -0 0</pose>
      <parent>rr_steering_wheel_link</parent>
      <child>rr_wheel_link</child>
      <axis>
        <xyz>0 1 0</xyz>
        <limit>
          <lower>-1e+16</lower>
          <upper>1e+16</upper>
        </limit>
        <dynamics>
          <spring_reference>0</spring_reference>
          <spring_stiffness>0</spring_stiffness>
        </dynamics>
      </axis>
    </joint>
    <link name='rr_wheel_link'>
      <pose relative_to='rr_wheel'>0 0 0 0 -0 0</pose>
      <inertial>
        <pose>0 0 0 0 -0 0</pose>
        <mass>8</mass>
        <inertia>
          <ixx>0.1171</ixx>
          <ixy>0</ixy>
          <ixz>0</ixz>
          <iyy>0.1361</iyy>
          <iyz>0</iyz>
          <izz>0.1171</izz>
        </inertia>
      </inertial>
      <collision name='rr_wheel_link_collision'>
        <pose>0 0 0 1.57 -0 0</pose>
        <geometry>
          <cylinder>
            <length>0.08</length>
            <radius>0.08</radius>
          </cylinder>
        </geometry>
      </collision>
      <visual name='rr_wheel_link_visual'>
        <pose>0 0 0 1.57 -0 0</pose>
        <geometry>
          <cylinder>
            <length>0.01</length>
            <radius>0.01</radius>
          </cylinder>
        </geometry>
      </visual>
    </link>

    <static>0</static>

    <plugin name="ranger_mini_joint_state" filename="libgazebo_ros_joint_state_publisher.so">
      <ros>
          <remapping>~/out:=joint_states</remapping>
      </ros>
      <update_rate>30</update_rate>
      <joint_name>fl_wheel</joint_name>
      <joint_name>fr_wheel</joint_name>
      <joint_name>rl_wheel</joint_name>
      <joint_name>rr_wheel</joint_name>
      <joint_name>fl_steering_wheel</joint_name>
      <joint_name>fr_steering_wheel</joint_name>
      <joint_name>rl_steering_wheel</joint_name>
      <joint_name>rr_steering_wheel</joint_name>
    </plugin>

    <ros2_control name="GazeboSystem" type="system">
        <hardware>
            <plugin>gazebo_ros2_control/GazeboSystem</plugin>
        </hardware>

        <joint name="fl_wheel">
            <param name="node_id">1</param>
            <command_interface name="velocity">
            <param name="min">-3.14</param>
            <param name="max">3.14</param>
            </command_interface>
            <state_interface name="velocity"/>
            <state_interface name="effort"/>
        </joint>

        <joint name="fr_wheel">
            <param name="node_id">4</param>
            <command_interface name="velocity">
            <param name="min">-3.14</param>
            <param name="max">3.14</param>
            </command_interface>
            <state_interface name="velocity"/>
            <state_interface name="effort"/>
        </joint>

        <joint name="rl_wheel">
            <param name="node_id">2</param>
            <command_interface name="velocity">
            <param name="min">-3.14</param>
            <param name="max">3.14</param>
            </command_interface>
            <state_interface name="velocity"/>
            <state_interface name="effort"/>
        </joint>

        <joint name="rr_wheel">
            <param name="node_id">3</param>
            <command_interface name="velocity">
            <param name="min">-3.14</param>
            <param name="max">3.14</param>
            </command_interface>
            <state_interface name="velocity"/>
            <state_interface name="effort"/>
        </joint>

        <joint name="fl_steering_wheel">
            <param name="node_id">5</param>
            <command_interface name="position">
            <param name="min">-3.14</param>
            <param name="max">3.14</param>
            </command_interface>
            <state_interface name="position">
            <param name="initial_value">0</param>
            </state_interface>
            <state_interface name="velocity"/>
            <state_interface name="effort"/>
        </joint>

        <joint name="fr_steering_wheel">
            <param name="node_id">8</param>
            <command_interface name="position">
            <param name="min">-3.14</param>
            <param name="max">3.14</param>
            </command_interface>
            <state_interface name="position">
            <param name="initial_value">0</param>
            </state_interface>
            <state_interface name="velocity"/>
            <state_interface name="effort"/>
        </joint>

        <joint name="rl_steering_wheel">
            <param name="node_id">6</param>
            <command_interface name="position">
            <param name="min">-3.14</param>
            <param name="max">3.14</param>
            </command_interface>
            <state_interface name="position">
            <param name="initial_value">0</param>
            </state_interface>
            <state_interface name="velocity"/>
            <state_interface name="effort"/>
        </joint>

        <joint name="rr_steering_wheel">
            <param name="node_id">7</param>
            <command_interface name="position">
            <param name="min">-3.14</param>
            <param name="max">3.14</param>
            </command_interface>
            <state_interface name="position">
            <param name="initial_value">0</param>
            </state_interface>
            <state_interface name="velocity"/>
            <state_interface name="effort"/>
        </joint>
    </ros2_control>

    <plugin name="gazebo_ros2_control" filename="libgazebo_ros2_control.so">
      <parameters>/home/nick/ranger_mini_v2/install/ranger_mini_v2/share/ranger_mini_v2/config/controllers.yaml</parameters>
    </plugin>

  </model>
</sdf>
