<?xml version="1.0" ?>
<!-- =================================================================================== -->
<!-- |    This document was autogenerated by xacro from /home/nvidia/ranger_mini_v2/install/ranger_mini_v2/share/ranger_mini_v2/urdf/ranger_mini.xacro | -->
<!-- |    EDITING THIS FILE BY HAND IS NOT RECOMMENDED                                 | -->
<!-- =================================================================================== -->
<robot name="ranger_mini_v2">
    <!-- Base link -->
    <link name="base_link">
        <visual>
            <origin rpy="1.57 0 3.14 " xyz="0 0 0"/>
            <geometry>
                <mesh filename="package://ranger_mini_v2/meshes/ranger_base.dae"/>
            </geometry>
        </visual>
        <collision>
            <origin rpy="0 0 0" xyz="0 0 0.008"/>
            <geometry>
                <box size="1 1 1"/>
            </geometry>
        </collision>
        <collision>
            <origin rpy="0 0 0" xyz="0 0 0"/>
            <geometry>
                <box size="1 1 1"/>
            </geometry>
        </collision>
    </link>
    <link name="fl_steering_wheel_link">
        <visual>
            <origin rpy="1.57 0 3.14 " xyz="0 0 0"/>
            <geometry>
                <cylinder length="0.001" radius="0.001"/>
            </geometry>
        </visual>
        <collision>
            <origin rpy="0 0 0" xyz="0 0 0.008"/>
            <geometry>
                <box size="1 1 1"/>
            </geometry>
        </collision>
        <collision>
            <origin rpy="0 0 0" xyz="0 0 0"/>
            <geometry>
                <cylinder length="0.001" radius="0.001"/>
            </geometry>
        </collision>
    </link>
    <joint name="fl_steering_wheel" type="revolute">
        <origin rpy="0 0 0" xyz="0.23 0.206 -0.1"/>
        <parent link="base_link"/>
        <child link="fl_steering_wheel_link"/>
        <axis rpy="0 0 0" xyz="0 0 1"/>
        <limit effort="5" lower="-2.1" upper="2.1" velocity="6.28"/>
    </joint>
    <link name="fl_wheel_link">
        <inertial>
            <mass value="8"/>
            <origin xyz="0 0 0"/>
            <inertia ixx="0.1171" ixy="0" ixz="0" iyy="0.1361" iyz="0" izz="0.1171"/>
        </inertial>
        <visual>
            <origin rpy="1.57 0 0" xyz="0.23 -0.2 0.1"/>
            <geometry>
                <mesh filename="package://ranger_mini_v2/meshes/fr.dae"/>
            </geometry>
        </visual>
        <collision>
            <origin rpy="0 0 0" xyz="0 0 0"/>
            <geometry>
                <cylinder length="0.1" radius="0.1"/>
            </geometry>
            <contact>
                <ode>
                    <min_depth>0.001</min_depth>
                </ode>
            </contact>
        </collision>
    </link>
    <joint name="fl_wheel" type="continuous">
        <origin rpy="0 0 0" xyz="0.0 0.0 0.0"/>
        <parent link="fl_steering_wheel_link"/>
        <child link="fl_wheel_link"/>
        <axis rpy="0 0 0" xyz="0 0 1"/>
    </joint>
    <link name="fr_steering_wheel_link">
        <visual>
            <origin rpy="1.57 0 3.14 " xyz="0 0 0"/>
            <geometry>
                <cylinder length="0.001" radius="0.001"/>
            </geometry>
        </visual>
        <collision>
            <origin rpy="0 0 0" xyz="0 0 0.008"/>
            <geometry>
                <box size="1 1 1"/>
            </geometry>
        </collision>
        <collision>
            <origin rpy="0 0 0" xyz="0 0 0"/>
            <geometry>
                <cylinder length="0.001" radius="0.001"/>
            </geometry>
        </collision>
    </link>
    <joint name="fr_steering_wheel" type="revolute">
        <origin rpy="0 0 0" xyz="0.23 -0.206 -0.1"/>
        <parent link="base_link"/>
        <child link="fr_steering_wheel_link"/>
        <axis rpy="0 0 0" xyz="0 0 1"/>
        <limit effort="5" lower="-2.1" upper="2.1" velocity="6.28"/>
    </joint>
    <link name="fr_wheel_link">
        <inertial>
            <mass value="8"/>
            <origin xyz="0 0 0"/>
            <inertia ixx="0.1171" ixy="0" ixz="0" iyy="0.1361" iyz="0" izz="0.1171"/>
        </inertial>
        <visual>
            <origin rpy="1.57 0 0" xyz="0.23 0.2 0.1"/>
            <geometry>
                <mesh filename="package://ranger_mini_v2/meshes/fl.dae"/>
            </geometry>
        </visual>
        <collision>
            <origin rpy="0 0 0" xyz="0 0 0"/>
            <geometry>
                <cylinder length="0.1" radius="0.1"/>
            </geometry>
            <contact>
                <ode>
                    <min_depth>0.001</min_depth>
                </ode>
            </contact>
        </collision>
    </link>
    <joint name="fr_wheel" type="continuous">
        <origin rpy="0 0 0" xyz="0.0 0.0 0.0"/>
        <parent link="fr_steering_wheel_link"/>
        <child link="fr_wheel_link"/>
        <axis rpy="0 0 0" xyz="0 0 1"/>
    </joint>
    <link name="rl_steering_wheel_link">
        <visual>
            <origin rpy="1.57 0 3.14 " xyz="0 0 0"/>
            <geometry>
                <cylinder length="0.001" radius="0.001"/>
            </geometry>
        </visual>
        <collision>
            <origin rpy="0 0 0" xyz="0 0 0.008"/>
            <geometry>
                <box size="1 1 1"/>
            </geometry>
        </collision>
        <collision>
            <origin rpy="0 0 0" xyz="0 0 0"/>
            <geometry>
                <cylinder length="0.001" radius="0.001"/>
            </geometry>
        </collision>
    </link>
    <joint name="rl_steering_wheel" type="revolute">
        <origin rpy="0 0 0" xyz="-0.23 0.206 -0.1"/>
        <parent link="base_link"/>
        <child link="rl_steering_wheel_link"/>
        <axis rpy="0 0 0" xyz="0 0 1"/>
        <limit effort="5" lower="-2.1" upper="2.1" velocity="6.28"/>
    </joint>
    <link name="rl_wheel_link">
        <inertial>
            <mass value="8"/>
            <origin xyz="0 0 0"/>
            <inertia ixx="0.1171" ixy="0" ixz="0" iyy="0.1361" iyz="0" izz="0.1171"/>
        </inertial>
        <visual>
            <origin rpy="1.57 0 0" xyz="0.23 -0.2 0.1"/>
            <geometry>
                <mesh filename="package://ranger_mini_v2/meshes/fr.dae"/>
            </geometry>
        </visual>
        <collision>
            <origin rpy="0 0 0" xyz="0 0 0"/>
            <geometry>
                <cylinder length="0.1" radius="0.1"/>
            </geometry>
            <contact>
                <ode>
                    <min_depth>0.001</min_depth>
                </ode>
            </contact>
        </collision>
    </link>
    <joint name="rl_wheel" type="continuous">
        <origin rpy="0 0 0" xyz="0.0 0.0 0.0 "/>
        <parent link="rl_steering_wheel_link"/>
        <child link="rl_wheel_link"/>
        <axis rpy="0 0 0" xyz="0 0 1"/>
    </joint>
    <link name="rr_steering_wheel_link">
        <visual>
            <origin rpy="1.57 0 3.14 " xyz="0 0 0"/>
            <geometry>
                <cylinder length="0.001" radius="0.001"/>
            </geometry>
        </visual>
        <collision>
            <origin rpy="0 0 0" xyz="0 0 0.008"/>
            <geometry>
                <box size="1 1 1"/>
            </geometry>
        </collision>
        <collision>
            <origin rpy="0 0 0" xyz="0 0 0"/>
            <geometry>
                <cylinder length="0.001" radius="0.001"/>
            </geometry>
        </collision>
    </link>
    <joint name="rr_steering_wheel" type="revolute">
        <origin rpy="0 0 0" xyz="-0.23 -0.206 -0.1"/>
        <parent link="base_link"/>
        <child link="rr_steering_wheel_link"/>
        <axis rpy="0 0 0" xyz="0 0 1"/>
        <limit effort="5" lower="-2.1" upper="2.1" velocity="6.28"/>
    </joint>
    <link name="rr_wheel_link">
        <inertial>
            <mass value="8"/>
            <origin xyz="0 0 0"/>
            <inertia ixx="0.1171" ixy="0" ixz="0" iyy="0.1361" iyz="0" izz="0.1171"/>
        </inertial>
        <visual>
            <origin rpy="1.57 0 0" xyz="0.23 0.2 0.1"/>
            <geometry>
                <mesh filename="package://ranger_mini_v2/meshes/fl.dae"/>
            </geometry>
        </visual>
        <collision>
            <origin rpy="0 0 0" xyz="0 0 0"/>
            <geometry>
                <cylinder length="0.1" radius="0.1"/>
            </geometry>
            <contact>
                <ode>
                    <min_depth>0.001</min_depth>
                </ode>
            </contact>
        </collision>
    </link>
    <joint name="rr_wheel" type="continuous">
        <origin rpy="0 0 0" xyz="0.0 0.0 0.0 "/>
        <parent link="rr_steering_wheel_link"/>
        <child link="rr_wheel_link"/>
        <axis rpy="0 0 0" xyz="0 0 1"/>
    </joint>
</robot>
