<sdf version='1.7'>
  <model name='rs_robot'>

    <link name="base_footprint"/>

    <link name='base_link'>
      <inertial>
        <pose>-0.003143 0 0.022 0 -0 0</pose>
        <mass>1.4</mass>
        <inertia>
          <ixx>0.0004846</ixx>
          <ixy>0</ixy>
          <ixz>0.000132</ixz>
          <iyy>0.000352971</iyy>
          <iyz>0</iyz>
          <izz>0.000339571</izz>
        </inertia>
      </inertial>
      <collision name='base_footprint_fixed_joint_lump__base_link_collision'>
        <pose>0 0 0 0 -0 0</pose>
        <geometry>
          <mesh>
            <scale>1 1 1</scale>
            <uri>model://rs_robot/meshes/STL/base/base_link.stl</uri>
          </mesh>
        </geometry>
        <surface>
          <contact>
            <ode/>
          </contact>
          <friction>
            <ode>
              <mu>0.05</mu>
              <mu2>0.05</mu2>
            </ode>
          </friction>
        </surface>
      </collision>
      <visual name='base_footprint_fixed_joint_lump__base_link_visual'>
        <pose>0 0 0 0 -0 0</pose>
        <geometry>
          <mesh>
            <scale>1 1 1</scale>
            <uri>model://rs_robot/meshes/DAE/base/base_link.dae</uri>
          </mesh>
        </geometry>
      </visual>
    </link>

    <joint name='fl_steering_joint' type='revolute'>
      <pose relative_to='base_link'>0.077 0.031 -0.004 0 -0 0</pose>
      <parent>base_link</parent>
      <child>fl_steering_link</child>
      <axis>
        <xyz>0 0 1</xyz>
        <limit>
          <lower>-2.1</lower>
          <upper>2.1</upper>
          <effort>5</effort>
          <velocity>6.28</velocity>
        </limit>
        <dynamics>
          <damping>0.005</damping>
          <friction>0.02</friction>
          <spring_reference>0</spring_reference>
          <spring_stiffness>0</spring_stiffness>
        </dynamics>
      </axis>
    </joint>
    <link name='fl_steering_link'>
      <pose relative_to='fl_steering_joint'>0 0 0 0 -0 0</pose>
      <inertial>
        <pose>0 0 -0.02 0 -0 0</pose>
        <mass>0.15</mass>
        <inertia>
          <ixx>1e-05</ixx>
          <ixy>0</ixy>
          <ixz>0</ixz>
          <iyy>1e-05</iyy>
          <iyz>0</iyz>
          <izz>4e-06</izz>
        </inertia>
      </inertial>
      <collision name='fl_steering_link_collision'>
        <pose>0 0 0 0 -0 0</pose>
        <geometry>
          <mesh>
            <scale>1 1 1</scale>
            <uri>model://rs_robot/meshes/STL/suspension/sus_link.stl</uri>
          </mesh>
        </geometry>
        <surface>
          <contact>
            <ode/>
          </contact>
          <friction>
            <ode>
              <mu>0.05</mu>
              <mu2>0.05</mu2>
            </ode>
          </friction>
        </surface>
      </collision>
      <visual name='fl_steering_link_visual'>
        <pose>0 0 0 0 -0 0</pose>
        <geometry>
          <mesh>
            <scale>1 1 1</scale>
            <uri>model://rs_robot/meshes/DAE/suspension/front_left_link.dae</uri>
          </mesh>
        </geometry>
      </visual>
      <self_collide>0</self_collide>
    </link>
    <joint name='fl_wheel_joint' type='revolute'>
      <pose relative_to='fl_steering_link'>0 0.021 -0.025 0 0 -3.14159</pose>
      <parent>fl_steering_link</parent>
      <child>fl_wheel_link</child>
      <axis>
        <xyz>0 -1 0</xyz>
        <limit>
          <effort>1.5</effort>
          <velocity>20</velocity>
          <lower>-1e+16</lower>
          <upper>1e+16</upper>
        </limit>
        <dynamics>
          <damping>0.005</damping>
          <friction>0.02</friction>
          <spring_reference>0</spring_reference>
          <spring_stiffness>0</spring_stiffness>
        </dynamics>
      </axis>
    </joint>
    <link name='fl_wheel_link'>
      <pose relative_to='fl_wheel_joint'>0 0 0 0 -0 0</pose>
      <inertial>
        <pose>0 -0.007 0 0 -0 0</pose>
        <mass>0.05</mass>
        <inertia>
          <ixx>1e-05</ixx>
          <ixy>0</ixy>
          <ixz>0</ixz>
          <iyy>1.8e-05</iyy>
          <iyz>0</iyz>
          <izz>1e-05</izz>
        </inertia>
      </inertial>
      <collision name='fl_wheel_link_collision'>
        <pose>0 0 0 0 -0 0</pose>
        <geometry>
          <mesh>
            <scale>1 1 1</scale>
            <uri>model://rs_robot/meshes/STL/wheel/robot_wheel.stl</uri>
          </mesh>
        </geometry>
      </collision>
      <visual name='fl_wheel_link_visual'>
        <pose>0 0 0 0 -0 0</pose>
        <geometry>
          <mesh>
            <scale>1 1 1</scale>
            <uri>model://rs_robot/meshes/DAE/wheel/wheel_link.dae</uri>
          </mesh>
        </geometry>
      </visual>
    </link>
    <joint name='fr_steering_joint' type='revolute'>
      <pose relative_to='base_link'>0.077 -0.031 -0.004 0 -0 0</pose>
      <parent>base_link</parent>
      <child>fr_steering_link</child>
      <axis>
        <xyz>0 0 1</xyz>
        <limit>
          <lower>-2.1</lower>
          <upper>2.1</upper>
          <effort>5</effort>
          <velocity>6.28</velocity>
        </limit>
        <dynamics>
          <damping>0.005</damping>
          <friction>0.02</friction>
          <spring_reference>0</spring_reference>
          <spring_stiffness>0</spring_stiffness>
        </dynamics>
      </axis>
    </joint>
    <link name='fr_steering_link'>
      <pose relative_to='fr_steering_joint'>0 0 0 0 -0 0</pose>
      <inertial>
        <pose>0 0 -0.02 0 -0 0</pose>
        <mass>0.15</mass>
        <inertia>
          <ixx>1e-05</ixx>
          <ixy>0</ixy>
          <ixz>0</ixz>
          <iyy>1e-05</iyy>
          <iyz>0</iyz>
          <izz>4e-06</izz>
        </inertia>
      </inertial>
      <collision name='fr_steering_link_collision'>
        <pose>0 0 0 0 -0 0</pose>
        <geometry>
          <mesh>
            <scale>1 1 1</scale>
            <uri>model://rs_robot/meshes/STL/suspension/sus_link.stl</uri>
          </mesh>
        </geometry>
        <surface>
          <contact>
            <ode/>
          </contact>
          <friction>
            <ode>
              <mu>0.05</mu>
              <mu2>0.05</mu2>
            </ode>
          </friction>
        </surface>
      </collision>
      <visual name='fr_steering_link_visual'>
        <pose>0 0 0 0 -0 0</pose>
        <geometry>
          <mesh>
            <scale>1 1 1</scale>
            <uri>model://rs_robot/meshes/DAE/suspension/front_right_link.dae</uri>
          </mesh>
        </geometry>
      </visual>
      <self_collide>0</self_collide>
    </link>
    <joint name='fr_wheel_joint' type='revolute'>
      <pose relative_to='fr_steering_link'>0 -0.021 -0.025 0 -0 0</pose>
      <parent>fr_steering_link</parent>
      <child>fr_wheel_link</child>
      <axis>
        <xyz>0 1 0</xyz>
        <limit>
          <effort>1.5</effort>
          <velocity>20</velocity>
          <lower>-1e+16</lower>
          <upper>1e+16</upper>
        </limit>
        <dynamics>
          <damping>0.005</damping>
          <friction>0.02</friction>
          <spring_reference>0</spring_reference>
          <spring_stiffness>0</spring_stiffness>
        </dynamics>
      </axis>
    </joint>
    <link name='fr_wheel_link'>
      <pose relative_to='fr_wheel_joint'>0 0 0 0 -0 0</pose>
      <inertial>
        <pose>0 -0.007 0 0 -0 0</pose>
        <mass>0.05</mass>
        <inertia>
          <ixx>1e-05</ixx>
          <ixy>0</ixy>
          <ixz>0</ixz>
          <iyy>1.8e-05</iyy>
          <iyz>0</iyz>
          <izz>1e-05</izz>
        </inertia>
      </inertial>
      <collision name='fr_wheel_link_collision'>
        <pose>0 0 0 0 -0 0</pose>
        <geometry>
          <mesh>
            <scale>1 1 1</scale>
            <uri>model://rs_robot/meshes/STL/wheel/robot_wheel.stl</uri>
          </mesh>
        </geometry>
      </collision>
      <visual name='fr_wheel_link_visual'>
        <pose>0 0 0 0 -0 0</pose>
        <geometry>
          <mesh>
            <scale>1 1 1</scale>
            <uri>model://rs_robot/meshes/DAE/wheel/wheel_link.dae</uri>
          </mesh>
        </geometry>
      </visual>
    </link>
    
    <joint name='rl_steering_joint' type='revolute'>
      <pose relative_to='base_link'>-0.077 0.031 -0.004 0 -0 0</pose>
      <parent>base_link</parent>
      <child>rl_steering_link</child>
      <axis>
        <xyz>0 0 1</xyz>
        <limit>
          <lower>-2.1</lower>
          <upper>2.1</upper>
          <effort>5</effort>
          <velocity>6.28</velocity>
        </limit>
        <dynamics>
          <damping>0.005</damping>
          <friction>0.02</friction>
          <spring_reference>0</spring_reference>
          <spring_stiffness>0</spring_stiffness>
        </dynamics>
      </axis>
    </joint>
    <link name='rl_steering_link'>
      <pose relative_to='rl_steering_joint'>0 0 0 0 -0 0</pose>
      <inertial>
        <pose>0 0 -0.02 0 -0 0</pose>
        <mass>0.15</mass>
        <inertia>
          <ixx>1e-05</ixx>
          <ixy>0</ixy>
          <ixz>0</ixz>
          <iyy>1e-05</iyy>
          <iyz>0</iyz>
          <izz>4e-06</izz>
        </inertia>
      </inertial>
      <collision name='rl_steering_link_collision'>
        <pose>0 0 0 0 -0 0</pose>
        <geometry>
          <mesh>
            <scale>1 1 1</scale>
            <uri>model://rs_robot/meshes/STL/suspension/sus_link.stl</uri>
          </mesh>
        </geometry>
        <surface>
          <contact>
            <ode/>
          </contact>
          <friction>
            <ode>
              <mu>0.05</mu>
              <mu2>0.05</mu2>
            </ode>
          </friction>
        </surface>
      </collision>
      <visual name='rl_steering_link_visual'>
        <pose>0 0 0 0 -0 0</pose>
        <geometry>
          <mesh>
            <scale>1 1 1</scale>
            <uri>model://rs_robot/meshes/DAE/suspension/rear_left_link.dae</uri>
          </mesh>
        </geometry>
      </visual>
      <self_collide>0</self_collide>
    </link>
    <joint name='rl_wheel_joint' type='revolute'>
      <pose relative_to='rl_steering_link'>0 0.021 -0.025 0 0 -3.14159</pose>
      <parent>rl_steering_link</parent>
      <child>rl_wheel_link</child>
      <axis>
        <xyz>0 -1 0</xyz>
        <limit>
          <effort>1.5</effort>
          <velocity>20</velocity>
          <lower>-1e+16</lower>
          <upper>1e+16</upper>
        </limit>
        <dynamics>
          <damping>0.005</damping>
          <friction>0.02</friction>
          <spring_reference>0</spring_reference>
          <spring_stiffness>0</spring_stiffness>
        </dynamics>
      </axis>
    </joint>
    <link name='rl_wheel_link'>
      <pose relative_to='rl_wheel_joint'>0 0 0 0 -0 0</pose>
      <inertial>
        <pose>0 -0.007 0 0 -0 0</pose>
        <mass>0.05</mass>
        <inertia>
          <ixx>1e-05</ixx>
          <ixy>0</ixy>
          <ixz>0</ixz>
          <iyy>1.8e-05</iyy>
          <iyz>0</iyz>
          <izz>1e-05</izz>
        </inertia>
      </inertial>
      <collision name='rl_wheel_link_collision'>
        <pose>0 0 0 0 -0 0</pose>
        <geometry>
          <mesh>
            <scale>1 1 1</scale>
            <uri>model://rs_robot/meshes/STL/wheel/robot_wheel.stl</uri>
          </mesh>
        </geometry>
      </collision>
      <visual name='rl_wheel_link_visual'>
        <pose>0 0 0 0 -0 0</pose>
        <geometry>
          <mesh>
            <scale>1 1 1</scale>
            <uri>model://rs_robot/meshes/DAE/wheel/wheel_link.dae</uri>
          </mesh>
        </geometry>
      </visual>
    </link>
    <joint name='rr_steering_joint' type='revolute'>
      <pose relative_to='base_link'>-0.077 -0.031 -0.004 0 -0 0</pose>
      <parent>base_link</parent>
      <child>rr_steering_link</child>
      <axis>
        <xyz>0 0 1</xyz>
        <limit>
          <lower>-2.1</lower>
          <upper>2.1</upper>
          <effort>5</effort>
          <velocity>6.28</velocity>
        </limit>
        <dynamics>
          <damping>0.005</damping>
          <friction>0.02</friction>
          <spring_reference>0</spring_reference>
          <spring_stiffness>0</spring_stiffness>
        </dynamics>
      </axis>
    </joint>
    <link name='rr_steering_link'>
      <pose relative_to='rr_steering_joint'>0 0 0 0 -0 0</pose>
      <inertial>
        <pose>0 0 -0.02 0 -0 0</pose>
        <mass>0.15</mass>
        <inertia>
          <ixx>1e-05</ixx>
          <ixy>0</ixy>
          <ixz>0</ixz>
          <iyy>1e-05</iyy>
          <iyz>0</iyz>
          <izz>4e-06</izz>
        </inertia>
      </inertial>
      <collision name='rr_steering_link_collision'>
        <pose>0 0 0 0 -0 0</pose>
        <geometry>
          <mesh>
            <scale>1 1 1</scale>
            <uri>model://rs_robot/meshes/STL/suspension/sus_link.stl</uri>
          </mesh>
        </geometry>
        <surface>
          <contact>
            <ode/>
          </contact>
          <friction>
            <ode>
              <mu>0.05</mu>
              <mu2>0.05</mu2>
            </ode>
          </friction>
        </surface>
      </collision>
      <visual name='rr_steering_link_visual'>
        <pose>0 0 0 0 -0 0</pose>
        <geometry>
          <mesh>
            <scale>1 1 1</scale>
            <uri>model://rs_robot/meshes/DAE/suspension/rear_right_link.dae</uri>
          </mesh>
        </geometry>
      </visual>
      <self_collide>0</self_collide>
    </link>
    <joint name='rr_wheel_joint' type='revolute'>
      <pose relative_to='rr_steering_link'>0 -0.021 -0.025 0 -0 0</pose>
      <parent>rr_steering_link</parent>
      <child>rr_wheel_link</child>
      <axis>
        <xyz>0 1 0</xyz>
        <limit>
          <effort>1.5</effort>
          <velocity>20</velocity>
          <lower>-1e+16</lower>
          <upper>1e+16</upper>
        </limit>
        <dynamics>
          <damping>0.005</damping>
          <friction>0.02</friction>
          <spring_reference>0</spring_reference>
          <spring_stiffness>0</spring_stiffness>
        </dynamics>
      </axis>
    </joint>
    <link name='rr_wheel_link'>
      <pose relative_to='rr_wheel_joint'>0 0 0 0 -0 0</pose>
      <inertial>
        <pose>0 -0.007 0 0 -0 0</pose>
        <mass>0.05</mass>
        <inertia>
          <ixx>1e-05</ixx>
          <ixy>0</ixy>
          <ixz>0</ixz>
          <iyy>1.8e-05</iyy>
          <iyz>0</iyz>
          <izz>1e-05</izz>
        </inertia>
      </inertial>
      <collision name='rr_wheel_link_collision'>
        <pose>0 0 0 0 -0 0</pose>
        <geometry>
          <mesh>
            <scale>1 1 1</scale>
            <uri>model://rs_robot/meshes/STL/wheel/robot_wheel.stl</uri>
          </mesh>
        </geometry>
      </collision>
      <visual name='rr_wheel_link_visual'>
        <pose>0 0 0 0 -0 0</pose>
        <geometry>
          <mesh>
            <scale>1 1 1</scale>
            <uri>model://rs_robot/meshes/DAE/wheel/wheel_link.dae</uri>
          </mesh>
        </geometry>
      </visual>
    </link>

  </model>
</sdf>
